Workbook
Name UNIDAD: #REF!

Sheet Hoja1

Sheet Paradas Ilpea
K1: CONTROL DE OCUPACION DE USUARIOS POR RUTA
A2: Cliente: ILPEA | C2: ILPEA
C3: Lunes | G3: Martes | K3: Miércoles | O3: Jueves | S3: Viernes | W3: Sábado | Z3: Domingo
A4: Ruta | B4: Parada | C4: 46090 | G4: =C4+1 -> 46091 | K4: =G4+1 -> 46092 | O4: =K4+1 -> 46093 | S4: =O4+1 -> 46094 | W4: =S4+1 -> 46095 | Z4: =W4+1 -> 46096
C5: 1er Turno | D5: 2do Turno | E5: Mixto | F5: 3er Turno | G5: 1er Turno | H5: 2do Turno | I5: Mixto | J5: 3er Turno | K5: 1er Turno | L5: 2do Turno | M5: Mixto | N5: 3er Turno | O5: 1er Turno | P5: 2do Turno | Q5: Mixto | R5: 3er Turno | S5: 1er Turno | T5: 2do Turno | U5: Mixto | V5: 3er Turno | W5: 1er Turno | X5: 2do Turno | Y5: 3er Turno | Z5: 1er Turno | AA5: 2do Turno | AB5: 3er Turno
C6: # Personal | D6: # Personal | E6: # Personal | F6: # Personal | G6: # Personal | H6: # Personal | I6: # Personal | J6: # Personal | K6: # Personal | L6: # Personal | M6: # Personal | N6: # Personal | O6: # Personal | P6: # Personal | Q6: # Personal | R6: # Personal | S6: # Personal | T6: # Personal | U6: # Personal | V6: # Personal | W6: # Personal | X6: # Personal | Y6: # Personal | Z6: # Personal | AA6: # Personal | AB6: # Personal
A7: 1 | B7: 1 | C7: 0 | D7: 4 | E7: 0 | F7: 0 | G7: 0 | H7: 3 | I7: 0 | J7: 0 | K7: 0 | L7: 2 | M7: 0 | N7: 0 | O7: 0 | P7: 4 | Q7: 0 | R7: 0 | S7: 0 | T7: 4 | U7: 0 | V7: 0 | W7: 0 | X7: 4 | Y7: 0 | Z7: 0 | AA7: 0 | AB7: 0
A8: 1 | B8: 2 | C8: 1 | D8: 1 | E8: 0 | F8: 1 | G8: 1 | H8: 1 | I8: 0 | J8: 1 | K8: 1 | L8: 1 | M8: 0 | N8: 1 | O8: 1 | P8: 1 | Q8: 0 | R8: 1 | S8: 1 | T8: 1 | U8: 0 | V8: 1 | W8: 1 | X8: 1 | Y8: 0 | Z8: 0 | AA8: 0 | AB8: 0
A9: 1 | B9: 3 | C9: 2 | D9: 2 | E9: 0 | F9: 1 | G9: 2 | H9: 2 | I9: 0 | J9: 1 | K9: 2 | L9: 2 | M9: 0 | N9: 1 | O9: 2 | P9: 2 | Q9: 0 | R9: 1 | S9: 2 | T9: 2 | U9: 0 | V9: 1 | W9: 2 | X9: 2 | Y9: 0 | Z9: 0 | AA9: 0 | AB9: 0
A10: 1 | B10: 4 | C10: 1 | D10: 0 | E10: 0 | F10: 0 | G10: 1 | H10: 0 | I10: 0 | J10: 0 | K10: 1 | L10: 0 | M10: 0 | N10: 0 | O10: 1 | P10: 0 | Q10: 0 | R10: 0 | S10: 1 | T10: 0 | U10: 0 | V10: 0 | W10: 1 | X10: 0 | Y10: 0 | Z10: 0 | AA10: 0 | AB10: 0
A11: 1 | B11: 5 | C11: 0 | D11: 7 | E11: 0 | F11: 2 | G11: 0 | H11: 7 | I11: 0 | J11: 2 | K11: 0 | L11: 7 | M11: 0 | N11: 2 | O11: 0 | P11: 7 | Q11: 0 | R11: 2 | S11: 0 | T11: 7 | U11: 0 | V11: 2 | W11: 0 | X11: 7 | Y11: 0 | Z11: 0 | AA11: 0 | AB11: 0
A12: 1 | B12: 6 | C12: 0 | D12: 0 | E12: 0 | F12: 0 | G12: 0 | H12: 0 | I12: 0 | J12: 0 | K12: 0 | L12: 0 | M12: 0 | N12: 0 | O12: 0 | P12: 0 | Q12: 0 | R12: 0 | S12: 0 | T12: 0 | U12: 0 | V12: 0 | W12: 0 | X12: 0 | Y12: 0 | Z12: 0 | AA12: 0 | AB12: 0
A13: 1 | B13: 7 | C13: 0 | D13: 1 | E13: 0 | F13: 0 | G13: 0 | H13: 1 | I13: 0 | J13: 0 | K13: 0 | L13: 1 | M13: 0 | N13: 0 | O13: 0 | P13: 1 | Q13: 0 | R13: 0 | S13: 0 | T13: 1 | U13: 0 | V13: 0 | W13: 0 | X13: 1 | Y13: 0 | Z13: 0 | AA13: 0 | AB13: 0
A14: 1 | B14: 8 | C14: 0 | D14: 1 | E14: 0 | F14: 3 | G14: 0 | H14: 1 | I14: 0 | J14: 3 | K14: 0 | L14: 1 | M14: 0 | N14: 3 | O14: 0 | P14: 1 | Q14: 0 | R14: 3 | S14: 0 | T14: 1 | U14: 0 | V14: 3 | W14: 0 | X14: 1 | Y14: 0 | Z14: 0 | AA14: 0 | AB14: 0
A15: 1 | B15: 9 | C15: 3 | D15: 1 | E15: 0 | F15: 2 | G15: 3 | H15: 1 | I15: 0 | J15: 2 | K15: 3 | L15: 1 | M15: 0 | N15: 2 | O15: 3 | P15: 1 | Q15: 0 | R15: 2 | S15: 3 | T15: 1 | U15: 0 | V15: 2 | W15: 3 | X15: 1 | Y15: 0 | Z15: 0 | AA15: 0 | AB15: 0
A16: 1 | B16: 10 | C16: 5 | D16: 1 | E16: 1 | F16: 1 | G16: 5 | H16: 1 | I16: 1 | J16: 1 | K16: 5 | L16: 1 | M16: 1 | N16: 1 | O16: 5 | P16: 1 | Q16: 1 | R16: 1 | S16: 5 | T16: 1 | U16: 1 | V16: 1 | W16: 3 | X16: 1 | Y16: 0 | Z16: 0 | AA16: 0 | AB16: 0
A17: 1 | B17: 11 | C17: 3 | D17: 3 | E17: 0 | F17: 0 | G17: 3 | H17: 3 | I17: 0 | J17: 0 | K17: 3 | L17: 3 | M17: 0 | N17: 0 | O17: 3 | P17: 3 | Q17: 0 | R17: 0 | S17: 3 | T17: 3 | U17: 0 | V17: 0 | W17: 0 | X17: 3 | Y17: 0 | Z17: 0 | AA17: 0 | AB17: 0
A18: 1 | B18: 12 | C18: 9 | D18: 5 | E18: 0 | F18: 3 | G18: 9 | H18: 5 | I18: 0 | J18: 3 | K18: 8 | L18: 5 | M18: 0 | N18: 3 | O18: 9 | P18: 5 | Q18: 0 | R18: 3 | S18: 9 | T18: 5 | U18: 0 | V18: 3 | W18: 9 | X18: 5 | Y18: 0 | Z18: 0 | AA18: 0 | AB18: 0
... A30: 2 | B30: 12 | C30: 0 | D30: 0 | E30: 0 | F30: 0 | G30: 0 | H30: 0 | I30: 0 | J30: 0 | K30: 0 | L30: 0 | M30: 0 | N30: 0 | O30: 0 | P30: 0 | Q30: 0 | R30: 0 | S30: 0 | T30: 0 | U30: 0 | V30: 0 | W30: 0 | X30: 12 | Y30: 0 | Z30: 0 | AA30: 0 | AB30: 0
A31: 2 | B31: 13 | C31: 1 | D31: 1 | E31: 0 | F31: 2 | G31: 1 | H31: 1 | I31: 0 | J31: 2 | K31: 1 | L31: 1 | M31: 0 | N31: 2 | O31: 1 | P31: 1 | Q31: 0 | R31: 2 | S31: 1 | T31: 1 | U31: 0 | V31: 2 | W31: 1 | X31: 1 | Y31: 0 | Z31: 0
A32: 2 | B32: 14 | C32: 2 | D32: 1 | E32: 0 | F32: 2 | G32: 2 | H32: 1 | I32: 0 | J32: 2 | K32: 2 | L32: 1 | M32: 0 | N32: 2 | O32: 2 | P32: 1 | Q32: 0 | R32: 2 | S32: 2 | T32: 1 | U32: 0 | V32: 2 | W32: 2 | X32: 1 | Y32: 0 | Z32: 0
A33: 3 | B33: 1 | C33: 0 | D33: 1 | E33: 0 | F33: 0 | G33: 0 | H33: 1 | I33: 0 | J33: 0 | K33: 0 | L33: 1 | M33: 0 | N33: 0 | O33: 0 | P33: 1 | Q33: 0 | R33: 0 | S33: 0 | T33: 1 | U33: 0 | V33: 0 | W33: 0 | X33: 0 | Y33: 0 | Z33: 0 | AA33: 0 | AB33: 0
A34: 3 | B34: 2 | C34: 2 | D34: 1 | E34: 0 | F34: 0 | G34: 2 | H34: 1 | I34: 0 | J34: 0 | K34: 2 | L34: 1 | M34: 0 | N34: 0 | O34: 2 | P34: 1 | Q34: 0 | R34: 0 | S34: 2 | T34: 1 | U34: 0 | V34: 0 | W34: 2 | X34: 0 | Y34: 0 | Z34: 0 | AA34: 0 | AB34: 0
A35: 3 | B35: 3 | C35: 2 | D35: 0 | E35: 0 | F35: 0 | G35: 1 | H35: 0 | I35: 0 | J35: 0 | K35: 2 | L35: 0 | M35: 0 | N35: 0 | O35: 2 | P35: 0 | Q35: 0 | R35: 0 | S35: 2 | T35: 0 | U35: 0 | V35: 0 | W35: 2 | X35: 0 | Y35: 1 | Z35: 0 | AA35: 0 | AB35: 0
A36: 3 | B36: 4 | C36: 0 | D36: 0 | E36: 1 | F36: 0 | G36: 0 | H36: 0 | I36: 1 | J36: 0 | K36: 0 | L36: 0 | M36: 1 | N36: 0 | O36: 0 | P36: 0 | Q36: 1 | R36: 0 | S36: 0 | T36: 0 | U36: 1 | V36: 0 | W36: 0 | X36: 0 | Y36: 0 | Z36: 0 | AA36: 0 | AB36: 0
A37: 3 | B37: 5 | C37: 0 | D37: 0 | E37: 0 | F37: 0 | G37: 0 | H37: 0 | I37: 0 | J37: 0 | K37: 0 | L37: 0 | M37: 0 | N37: 0 | O37: 0 | P37: 0 | Q37: 0 | R37: 0 | S37: 0 | T37: 0 | U37: 0 | V37: 0 | W37: 0 | X37: 0 | Y37: 0 | Z37: 0 | AA37: 0 | AB37: 0
A38: 3 | B38: 6 | C38: 0 | D38: 0 | E38: 0 | F38: 1 | G38: 0 | H38: 0 | I38: 0 | J38: 1 | K38: 0 | L38: 0 | M38: 0 | N38: 1 | O38: 0 | P38: 0 | Q38: 0 | R38: 1 | S38: 0 | T38: 0 | U38: 0 | V38: 1 | W38: 0 | X38: 1 | Y38: 0 | Z38: 0 | AA38: 0 | AB38: 0
A39: 3 | B39: 7 | C39: 1 | D39: 0 | E39: 0 | F39: 0 | G39: 1 | H39: 0 | I39: 0 | J39: 0 | K39: 1 | L39: 0 | M39: 0 | N39: 0 | O39: 1 | P39: 0 | Q39: 0 | R39: 0 | S39: 1 | T39: 0 | U39: 0 | V39: 0 | W39: 1 | X39: 0 | Y39: 0 | Z39: 0 | AA39: 0 | AB39: 0
A40: 4 | B40: 1 | C40: 0 | D40: 0 | E40: 0 | F40: 1 | G40: 0 | H40: 0 | I40: 0 | J40: 1 | K40: 0 | L40: 0 | M40: 0 | N40: 1 | O40: 0 | P40: 0 | Q40: 0 | R40: 1 | S40: 0 | T40: 0 | U40: 0 | V40: 1 | W40: 0 | X40: 1 | Y40: 0 | Z40: 0 | AA40: 0 | AB40: 0
A41: 4 | B41: 2 | C41: 0 | D41: 2 | E41: 0 | F41: 0 | G41: 0 | H41: 2 | I41: 0 | J41: 0 | K41: 0 | L41: 2 | M41: 0 | N41: 0 | O41: 0 | P41: 2 | Q41: 0 | R41: 0 | S41: 0 | T41: 2 | U41: 0 | V41: 0 | W41: 0 | X41: 0 | Y41: 0 | Z41: 0 | AA41: 0 | AB41: 0
A42: 4 | B42: 3 | C42: 1 | D42: 0 | E42: 0 | F42: 0 | G42: 1 | H42: 0 | I42: 0 | J42: 0 | K42: 1 | L42: 0 | M42: 0 | N42: 0 | O42: 1 | P42: 0 | Q42: 0 | R42: 0 | S42: 1 | T42: 0 | U42: 0 | V42: 0 | W42: 1 | X42: 0 | Y42: 0 | Z42: 0 | AA42: 0 | AB42: 0
A43: 4 | B43: 4 | C43: 1 | D43: 1 | E43: 0 | F43: 0 | G43: 1 | H43: 0 | I43: 0 | J43: 0 | K43: 1 | L43: 0 | M43: 0 | N43: 0 | O43: 1 | P43: 0 | Q43: 0 | R43: 0 | S43: 1 | T43: 0 | U43: 0 | V43: 0 | W43: 1 | X43: 0 | Y43: 0 | Z43: 0 | AA43: 0 | AB43: 0
A44: 4 | B44: 5 | C44: 0 | D44: 1 | E44: 0 | F44: 0 | G44: 0 | H44: 1 | I44: 0 | J44: 0 | K44: 0 | L44: 1 | M44: 0 | N44: 0 | O44: 0 | P44: 1 | Q44: 0 | R44: 0 | S44: 0 | T44: 1 | U44: 0 | V44: 0 | W44: 0 | X44: 0 | Y44: 0 | Z44: 0 | AA44: 0 | AB44: 0
... A72: 8 | B72: 7 | C72: 3 | D72: 1 | E72: 0 | F72: 0 | G72: 3 | H72: 1 | I72: 0 | J72: 0 | K72: 3 | L72: 1 | M72: 0 | N72: 0 | O72: 3 | P72: 1 | Q72: 0 | R72: 0 | S72: 3 | T72: 1 | U72: 0 | V72: 0 | W72: 0 | X72: 0 | Y72: 0 | Z72: 0 | AA72: 0 | AB72: 0
A73: 8 | B73: 8 | C73: 0 | D73: 1 | E73: 1 | F73: 0 | G73: 0 | H73: 1 | I73: 0 | J73: 1 | K73: 0 | L73: 0 | M73: 0 | N73: 1 | O73: 0 | P73: 1 | Q73: 1 | R73: 0 | S73: 1 | T73: 0 | U73: 0 | V73: 0 | W73: 1 | X73: 0 | Y73: 0
A74: 9 | B74: 1 | C74: 1 | D74: 1 | E74: 0 | F74: 0 | G74: 1 | H74: 1 | I74: 0 | J74: 0 | K74: 1 | L74: 1 | M74: 0 | N74: 0 | O74: 1 | P74: 1 | Q74: 0 | R74: 0 | S74: 1 | T74: 1 | U74: 0 | V74: 0 | W74: 0 | X74: 1 | Y74: 0 | Z74: 0 | AA74: 0 | AB74: 0
A75: 9 | B75: 2 | C75: 0 | D75: 0 | E75: 0 | F75: 0 | G75: 0 | H75: 0 | I75: 0 | J75: 0 | K75: 0 | L75: 0 | M75: 0 | N75: 0 | O75: 0 | P75: 0 | Q75: 0 | R75: 0 | S75: 0 | T75: 0 | U75: 0 | V75: 0 | W75: 0 | X75: 0 | Y75: 0 | Z75: 0 | AA75: 0 | AB75: 0
A76: 9 | B76: 3 | C76: 1 | D76: 0 | E76: 0 | F76: 0 | G76: 1 | H76: 0 | I76: 0 | J76: 0 | K76: 1 | L76: 0 | M76: 0 | N76: 0 | O76: 1 | P76: 0 | Q76: 0 | R76: 0 | S76: 1 | T76: 0 | U76: 0 | V76: 0 | W76: 1 | X76: 0 | Y76: 0 | Z76: 0 | AA76: 0 | AB76: 0
A77: 9 | B77: 4 | C77: 1 | D77: 0 | E77: 0 | F77: 0 | G77: 1 | H77: 0 | I77: 0 | J77: 0 | K77: 1 | L77: 0 | M77: 0 | N77: 0 | O77: 1 | P77: 0 | Q77: 0 | R77: 0 | S77: 1 | T77: 0 | U77: 0 | V77: 0 | W77: 0 | X77: 0 | Y77: 0 | Z77: 0 | AA77: 0 | AB77: 0
A78: 9 | B78: 5 | C78: 1 | D78: 0 | E78: 0 | F78: 1 | G78: 1 | H78: 0 | I78: 0 | J78: 1 | K78: 1 | L78: 0 | M78: 0 | N78: 1 | O78: 1 | P78: 0 | Q78: 0 | R78: 1 | S78: 1 | T78: 0 | U78: 0 | V78: 1 | W78: 0 | X78: 0 | Y78: 0 | Z78: 0 | AA78: 0 | AB78: 0
...

Sheet Aforos Ilpea
A3: Cliente: ILPEA | F3: Lunes | N3: Martes | V3: Miércoles | AD3: Jueves | AL3: Viernes | AT3: Sábado | AZ3: Domingo | BF3: Promedio Diario
A4: Ruta | B4: Capacidad de Asientos | C4: Tipo de Unidad | D4: Zona | E4: Referencia | F4: 46090 | N4: =F4+1 -> 46091 | V4: =N4+1 -> 46092 | AD4: =V4+1 -> 46093 | AL4: =AD4+1 -> 46094 | AT4: =AL4+1 -> 46095 | AZ4: =AT4+1 -> 46096
F5: 1er Turno | H5: 2do Turno | J5: Mixto | L5: 3er Turno | N5: 1er Turno | P5: 2do Turno | R5: Mixto | T5: 3er Turno | V5: 1er Turno | X5: 2do Turno | Z5: Mixto | AB5: 3er Turno | AD5: 1er Turno | AF5: 2do Turno | AH5: Mixto | AJ5: 3er Turno | AL5: 1er Turno | AN5: 2do Turno | AP5: Mixto | AR5: 3er Turno | AT5: 1er Turno | AV5: 2do Turno | AX5: 3er Turno | AZ5: 1er Turno | BB5: 2do Turno | BD5: 3er Turno
F6: # Personal | G6: % Ocupación | H6: # Personal | I6: % Ocupación | J6: # Personal | K6: % Ocupación | L6: # Personal | M6: % Ocupación | N6: # Personal | O6: % Ocupación | P6: # Personal | Q6: % Ocupación | R6: # Personal | S6: % Ocupación | T6: # Personal | U6: % Ocupación | V6: # Personal | W6: % Ocupación | X6: # Personal | Y6: % Ocupación | Z6: # Personal | AA6: % Ocupación | AB6: # Personal | AC6: % Ocupación | AD6: # Personal | AE6: % Ocupación | AF6: # Personal | AG6: % Ocupación | AH6: # Personal | AI6: % Ocupación | AJ6: # Personal | AK6: % Ocupación | AL6: # Personal | AM6: % Ocupación | AN6: # Personal | AO6: % Ocupación | AP6: # Personal | AQ6: % Ocupación | AR6: # Personal | AS6: % Ocupación | AT6: # Personal | AU6: % Ocupación | AV6: # Personal | AW6: % Ocupación | AX6: # Personal | AY6: % Ocupación | AZ6: # Personal | BA6: % Ocupación | BB6: # Personal | BC6: % Ocupación | BD6: # Personal | BE6: % Ocupación | BF6: Abordaje | BG6: Ocupacion
A7: 1 | B7: 37 | C7: Autobus | D7: Apaseo el Grande | E7: Canchas de futbol | F7: =SUM('Paradas Ilpea'!C7:C18) -> 24 | G7: =F7/B7 -> 0.64864865 | H7: =SUM('Paradas Ilpea'!D7:D18) -> 26 | I7: =H7/B7 -> 0.7027027 | J7: =SUM('Paradas Ilpea'!E7:E18) -> 1 | K7: =J7/B7 -> 0.027027027 | L7: =SUM('Paradas Ilpea'!F7:F18) -> 13 | M7: =L7/B7 -> 0.35135135 | N7: =SUM('Paradas Ilpea'!G7:G18) -> 24 | O7: =N7/B7 -> 0.64864865 | P7: =SUM('Paradas Ilpea'!H7:H18) -> 25 | Q7: =P7/B7 -> 0.67567568 | R7: =SUM('Paradas Ilpea'!I7:I18) -> 1 | S7: =R7/B7 -> 0.027027027 | T7: =SUM('Paradas Ilpea'!J7:J18) -> 13 | U7: =T7/B7 -> 0.35135135 | V7: =SUM('Paradas Ilpea'!K7:K18) -> 23 | W7: =V7/B7 -> 0.62162162 | X7: =SUM('Paradas Ilpea'!L7:L18) -> 24 | Y7: =X7/B7 -> 0.64864865 | Z7: =SUM('Paradas Ilpea'!M7:M18) -> 1 | AA7: =Z7/B7 -> 0.027027027 | AB7: =SUM('Paradas Ilpea'!N7:N18) -> 13 | AC7: =AB7/B7 -> 0.35135135 | AD7: =SUM('Paradas Ilpea'!O7:O18) -> 24 | AE7: =AD7/B7 -> 0.64864865 | AF7: =SUM('Paradas Ilpea'!P7:P18) -> 26 | AG7: =AF7/B7 -> 0.7027027 | AH7: =SUM('Paradas Ilpea'!Q7:Q18) -> 1 | AI7: =AH7/B7 -> 0.027027027 | AJ7: =SUM('Paradas Ilpea'!R7:R18) -> 13 | AK7: =AJ7/B7 -> 0.35135135 | AL7: =SUM('Paradas Ilpea'!S7:S18) -> 24 | AM7: =AL7/B7 -> 0.64864865 | AN7: =SUM('Paradas Ilpea'!T7:T18) -> 26 | AO7: =AN7/B7 -> 0.7027027 | AP7: =SUM('Paradas Ilpea'!U7:U18) -> 1 | AQ7: =AP7/B7 -> 0.027027027 | AR7: =SUM('Paradas Ilpea'!V7:V18) -> 13 | AS7: =AR7/B7 -> 0.35135135 | AT7: =SUM('Paradas Ilpea'!W7:W18) -> 19 | AU7: =AT7/B7 -> 0.51351351 | AV7: =SUM('Paradas Ilpea'!X7:X18) -> 26 | AW7: =AV7/B7 -> 0.7027027 | AX7: =SUM('Paradas Ilpea'!Y7:Y18) -> 0 | AY7: =AX7/B7 -> 0 | AZ7: =SUM('Paradas Ilpea'!Z7:Z18) -> 0 | BA7: =AZ7/B7 -> 0 | BB7: =SUM('Paradas Ilpea'!AA7:AA18) -> 0 | BC7: =BB7/B7 -> 0 | BD7: =SUM('Paradas Ilpea'!AB7:AB18) -> 0 | BE7: =BD7/B7 -> 0 | BF7: =AVERAGE(F7,H7,J7,L7,N7,P7,R7,V7,T7,X7,Z7,AB7,AD7,AF7,AH7,AJ7,AL7,AN7,,AP7,AR7,AT7,AV7,AX7,AZ7,BB7,BD7) -> 13.37037 | BG7: =AVERAGE(G7,I7,K7,M7,O7,Q7,S7,U7,W7,Y7,AA7,AC7,AE7,AG7,AI7,AK7,AM7,AO7,AQ7,AS7,AU7,AW7,AY7,BA7,BC7,BE7) -> 0.37525988
A8: 2 | B8: 37 | C8: Autobus | D8: Rancherías | E8: Capilla | F8: =SUM('Paradas Ilpea'!C19:C32) -> 24 | G8: =F8/B8 -> 0.64864865 | H8: =SUM('Paradas Ilpea'!D19:D32) -> 24 | I8: =H8/B8 -> 0.64864865 | J8: =SUM('Paradas Ilpea'!E19:E32) -> 3 | K8: =J8/B8 -> 0.081081081 | L8: =SUM('Paradas Ilpea'!F19:F32) -> 16 | M8: =L8/B8 -> 0.43243243 | N8: =SUM('Paradas Ilpea'!G19:G32) -> 25 | O8: =N8/B8 -> 0.67567568 | P8: =SUM('Paradas Ilpea'!H19:H32) -> 29 | Q8: =P8/B8 -> 0.78378378 | R8: =SUM('Paradas Ilpea'!I19:I32) -> 3 | S8: =R8/B8 -> 0.081081081 | T8: =SUM('Paradas Ilpea'!J19:J32) -> 15 | U8: =T8/B8 -> 0.40540541 | V8: =SUM('Paradas Ilpea'!K19:K32) -> 26 | W8: =V8/B8 -> 0.7027027 | X8: =SUM('Paradas Ilpea'!L19:L32) -> 29 | Y8: =X8/B8 -> 0.78378378 | Z8: =SUM('Paradas Ilpea'!M19:M32) -> 3 | AA8: =Z8/B8 -> 0.081081081 | AB8: =SUM('Paradas Ilpea'!N19:N32) -> 15 | AC8: =AB8/B8 -> 0.40540541 | AD8: =SUM('Paradas Ilpea'!O19:O32) -> 24 | AE8: =AD8/B8 -> 0.64864865 | AF8: =SUM('Paradas Ilpea'!P19:P32) -> 28 | AG8: =AF8/B8 -> 0.75675676 | AH8: =SUM('Paradas Ilpea'!Q19:Q32) -> 3 | AI8: =AH8/B8 -> 0.081081081 | AJ8: =SUM('Paradas Ilpea'!R19:R32) -> 15 | AK8: =AJ8/B8 -> 0.40540541 | AL8: =SUM('Paradas Ilpea'!S19:S32) -> 26 | AM8: =AL8/B8 -> 0.7027027 | AN8: =SUM('Paradas Ilpea'!T19:T32) -> 29 | AO8: =AN8/B8 -> 0.78378378 | AP8: =SUM('Paradas Ilpea'!U19:U32) -> 3 | AQ8: =AP8/B8 -> 0.081081081 | AR8: =SUM('Paradas Ilpea'!V19:V32) -> 15 | AS8: =AR8/B8 -> 0.40540541 | AT8: =SUM('Paradas Ilpea'!W19:W32) -> 21 | AU8: =AT8/B8 -> 0.56756757 | AV8: =SUM('Paradas Ilpea'!X19:X32) -> 25 | AW8: =AV8/B8 -> 0.67567568 | AX8: =SUM('Paradas Ilpea'!Y19:Y32) -> 0 | AY8: =AX8/B8 -> 0 | AZ8: =SUM('Paradas Ilpea'!Z19:Z32) -> 0 | BA8: =AZ8/B8 -> 0 | BB8: =SUM('Paradas Ilpea'!AA19:AA32) -> 0 | BC8: =BB8/B8 -> 0 | BD8: =SUM('Paradas Ilpea'!AB19:AB32) -> 0 | BE8: =BD8/B8 -> 0 | BF8: =AVERAGE(F8,H8,J8,L8,N8,P8,R8,V8,T8,X8,Z8,AB8,AD8,AF8,AH8,AJ8,AL8,AN8,,AP8,AR8,AT8,AV8,AX8,AZ8,BB8,BD8) -> 14.851852 | BG8: =AVERAGE(G8,I8,K8,M8,O8,Q8,S8,U8,W8,Y8,AA8,AC8,AE8,AG8,AI8,AK8,AM8,AO8,AQ8,AS8,AU8,AW8,AY8,BA8,BC8,BE8) -> 0.41683992
A9: 3 | B9: 13 | C9: Van | D9: Qro Obrera | E9: Oxxo | F9: =SUM('Paradas Ilpea'!C33:C39) -> 5 | G9: =F9/B9 -> 0.38461538 | H9: =SUM('Paradas Ilpea'!D33:D39) -> 2 | I9: =H9/B9 -> 0.15384615 | J9: =SUM('Paradas Ilpea'!E33:E39) -> 1 | K9: =J9/B9 -> 0.076923077 | L9: =SUM('Paradas Ilpea'!F33:F39) -> 1 | M9: =L9/B9 -> 0.076923077 | N9: =SUM('Paradas Ilpea'!G33:G39) -> 4 | O9: =N9/B9 -> 0.30769231 | P9: =SUM('Paradas Ilpea'!H33:H39) -> 2 | Q9: =P9/B9 -> 0.15384615 | R9: =SUM('Paradas Ilpea'!I33:I39) -> 1 | S9: =R9/B9 -> 0.076923077 | T9: =SUM('Paradas Ilpea'!J33:J39) -> 1 | U9: =T9/B9 -> 0.076923077 | V9: =SUM('Paradas Ilpea'!K33:K39) -> 5 | W9: =V9/B9 -> 0.38461538 | X9: =SUM('Paradas Ilpea'!L33:L39) -> 2 | Y9: =X9/B9 -> 0.15384615 | Z9: =SUM('Paradas Ilpea'!M33:M39) -> 1 | AA9: =Z9/B9 -> 0.076923077 | AB9: =SUM('Paradas Ilpea'!N33:N39) -> 1 | AC9: =AB9/B9 -> 0.076923077 | AD9: =SUM('Paradas Ilpea'!O33:O39) -> 5 | AE9: =AD9/B9 -> 0.38461538 | AF9: =SUM('Paradas Ilpea'!P33:P39) -> 2 | AG9: =AF9/B9 -> 0.15384615 | AH9: =SUM('Paradas Ilpea'!Q33:Q39) -> 1 | AI9: =AH9/B9 -> 0.076923077 | AJ9: =SUM('Paradas Ilpea'!R33:R39) -> 1 | AK9: =AJ9/B9 -> 0.076923077 | AL9: =SUM('Paradas Ilpea'!S33:S39) -> 5 | AM9: =AL9/B9 -> 0.38461538 | AN9: =SUM('Paradas Ilpea'!T33:T39) -> 2 | AO9: =AN9/B9 -> 0.15384615 | AP9: =SUM('Paradas Ilpea'!U33:U39) -> 1 | AQ9: =AP9/B9 -> 0.076923077 | AR9: =SUM('Paradas Ilpea'!V33:V39) -> 1 | AS9: =AR9/B9 -> 0.076923077 | AT9: =SUM('Paradas Ilpea'!W33:W39) -> 5 | AU9: =AT9/B9 -> 0.38461538 | AV9: =SUM('Paradas Ilpea'!X33:X39) -> 1 | AW9: =AV9/B9 -> 0.076923077 | AX9: =SUM('Paradas Ilpea'!Y33:Y39) -> 1 | AY9: =AX9/B9 -> 0.076923077 | AZ9: =SUM('Paradas Ilpea'!Z33:Z39) -> 0 | BA9: =AZ9/B9 -> 0 | BB9: =SUM('Paradas Ilpea'!AA33:AA39) -> 0 | BC9: =BB9/B9 -> 0 | BD9: =SUM('Paradas Ilpea'!AB33:AB39) -> 0 | BE9: =BD9/B9 -> 0 | BF9: =AVERAGE(F9,H9,J9,L9,N9,P9,R9,V9,T9,X9,Z9,AB9,AD9,AF9,AH9,AJ9,AL9,AN9,,AP9,AR9,AT9,AV9,AX9,AZ9,BB9,BD9) -> 1.8888889 | BG9: =AVERAGE(G9,I9,K9,M9,O9,Q9,S9,U9,W9,Y9,AA9,AC9,AE9,AG9,AI9,AK9,AM9,AO9,AQ9,AS9,AU9,AW9,AY9,BA9,BC9,BE9) -> 0.15088757
A10: 4 | B10: 14 | C10: Van | D10: Qro Carrillo | E10: Bodega Aurrera | F10: =SUM('Paradas Ilpea'!C40:C51) -> 8 | G10: =F10/B10 -> 0.57142857 | H10: =SUM('Paradas Ilpea'!D40:D51) -> 4 | I10: =H10/B10 -> 0.28571429 | J10: =SUM('Paradas Ilpea'!E40:E51) -> 1 | K10: =J10/B10 -> 0.071428571 | L10: =SUM('Paradas Ilpea'!F40:F51) -> 3 | M10: =L10/B10 -> 0.21428571 | N10: =SUM('Paradas Ilpea'!G40:G51) -> 9 | O10: =N10/B10 -> 0.64285714 | P10: =SUM('Paradas Ilpea'!H40:H51) -> 3 | Q10: =P10/B10 -> 0.21428571 | R10: =SUM('Paradas Ilpea'!I40:I51) -> 1 | S10: =R10/B10 -> 0.071428571 | T10: =SUM('Paradas Ilpea'!J40:J51) -> 3 | U10: =T10/B10 -> 0.21428571 | V10: =SUM('Paradas Ilpea'!K40:K51) -> 8 | W10: =V10/B10 -> 0.57142857 | X10: =SUM('Paradas Ilpea'!L40:L51) -> 3 | Y10: =X10/B10 -> 0.21428571 | Z10: =SUM('Paradas Ilpea'!M40:M51) -> 1 | AA10: =Z10/B10 -> 0.071428571 | AB10: =SUM('Paradas Ilpea'!N40:N51) -> 3 | AC10: =AB10/B10 -> 0.21428571 | AD10: =SUM('Paradas Ilpea'!O40:O51) -> 7 | AE10: =AD10/B10 -> 0.5 | AF10: =SUM('Paradas Ilpea'!P40:P51) -> 3 | AG10: =AF10/B10 -> 0.21428571 | AH10: =SUM('Paradas Ilpea'!Q40:Q51) -> 1 | AI10: =AH10/B10 -> 0.071428571 | AJ10: =SUM('Paradas Ilpea'!R41:R51) -> 2 | AK10: =AJ10/B10 -> 0.14285714 | AL10: =SUM('Paradas Ilpea'!S40:S51) -> 8 | AM10: =AL10/B10 -> 0.57142857 | AN10: =SUM('Paradas Ilpea'!T40:T51) -> 3 | AO10: =AN10/B10 -> 0.21428571 | AP10: =SUM('Paradas Ilpea'!U40:U51) -> 1 | AQ10: =AP10/B10 -> 0.071428571 | AR10: =SUM('Paradas Ilpea'!V40:V51) -> 3 | AS10: =AR10/B10 -> 0.21428571 | AT10: =SUM('Paradas Ilpea'!W41:W49) -> 7 | AU10: =AT10/B10 -> 0.5 | AV10: =SUM('Paradas Ilpea'!X40:X51) -> 3 | AW10: =AV10/B10 -> 0.21428571 | AX10: =SUM('Paradas Ilpea'!Y40:Y51) -> 0 | AY10: =AX10/B10 -> 0 | AZ10: =SUM('Paradas Ilpea'!Z40:Z51) -> 0 | BA10: =AZ10/B10 -> 0 | BB10: =SUM('Paradas Ilpea'!AA40:AA51) -> 0 | BC10: =BB10/B10 -> 0 | BD10: =SUM('Paradas Ilpea'!AB40:AB51) -> 0 | BE10: =BD10/B10 -> 0 | BF10: =AVERAGE(F10,H10,J10,L10,N10,P10,R10,V10,T10,X10,Z10,AB10,AD10,AF10,AH10,AJ10,AL10,AN10,,AP10,AR10,AT10,AV10,AX10,AZ10,BB10,BD10) -> 3.1481481 | BG10: =AVERAGE(G10,I10,K10,M10,O10,Q10,S10,U10,W10,Y10,AA10,AC10,AE10,AG10,AI10,AK10,AM10,AO10,AQ10,AS10,AU10,AW10,AY10,BA10,BC10,BE10) -> 0.23351648
A11: 6 | B11: 14 | C11: Van | D11: Fuentes de Balvanera | E11: Bodega Aurrera | F11: =SUM('Paradas Ilpea'!C52:C54) -> 3 | G11: =F11/B11 -> 0.21428571 | H11: =SUM('Paradas Ilpea'!D52:D54) -> 2 | I11: =H11/B11 -> 0.14285714 | J11: =SUM('Paradas Ilpea'!E52:E54) -> 0 | K11: =J11/B11 -> 0 | L11: =SUM('Paradas Ilpea'!F52:F54) -> 1 | M11: =L11/B11 -> 0.071428571 | N11: =SUM('Paradas Ilpea'!G52:G54) -> 3 | O11: =N11/B11 -> 0.21428571 | P11: =SUM('Paradas Ilpea'!H52:H54) -> 2 | Q11: =P11/B11 -> 0.14285714 | R11: =SUM('Paradas Ilpea'!I52:I54) -> 0 | S11: =R11/B11 -> 0 | T11: =SUM('Paradas Ilpea'!J52:J54) -> 1 | U11: =T11/B11 -> 0.071428571 | V11: =SUM('Paradas Ilpea'!K52:K54) -> 3 | W11: =V11/B11 -> 0.21428571 | X11: =SUM('Paradas Ilpea'!L52:L54) -> 1 | Y11: =X11/B11 -> 0.071428571 | Z11: =SUM('Paradas Ilpea'!M52:M54) -> 0 | AA11: =Z11/B11 -> 0 | AB11: =SUM('Paradas Ilpea'!N52:N54) -> 1 | AC11: =AB11/B11 -> 0.071428571 | AD11: =SUM('Paradas Ilpea'!O52:O54) -> 3 | AE11: =AD11/B11 -> 0.21428571 | AF11: =SUM('Paradas Ilpea'!P52:P54) -> 2 | AG11: =AF11/B11 -> 0.14285714 | AH11: =SUM('Paradas Ilpea'!Q52:Q54) -> 0 | AI11: =AH11/B11 -> 0 | AJ11: =SUM('Paradas Ilpea'!R52:R54) -> 1 | AK11: =AJ11/B11 -> 0.071428571 | AL11: =SUM('Paradas Ilpea'!S52:S54) -> 3 | AM11: =AL11/B11 -> 0.21428571 | AN11: =SUM('Paradas Ilpea'!T52:T54) -> 2 | AO11: =AN11/B11 -> 0.14285714 | AP11: =SUM('Paradas Ilpea'!U52:U54) -> 0 | AQ11: =AP11/B11 -> 0 | AR11: =SUM('Paradas Ilpea'!V52:V54) -> 1 | AS11: =AR11/B11 -> 0.071428571 | AT11: =SUM('Paradas Ilpea'!W52:W54) -> 0 | AU11: =AT11/B11 -> 0 | AV11: =SUM('Paradas Ilpea'!X52:X54) -> 0 | AW11: =AV11/B11 -> 0 | AX11: =SUM('Paradas Ilpea'!Y52:Y54) -> 0 | AY11: =AX11/B11 -> 0 | AZ11: =SUM('Paradas Ilpea'!Z52:Z54) -> 0 | BA11: =AZ11/B11 -> 0 | BB11: =SUM('Paradas Ilpea'!AA52:AA54) -> 0 | BC11: =BB11/B11 -> 0 | BD11: =SUM('Paradas Ilpea'!AB52:AB54) -> 0 | BE11: =BD11/B11 -> 0 | BF11: =AVERAGE(F11,H11,J11,L11,N11,P11,R11,V11,T11,X11,Z11,AB11,AD11,AF11,AH11,AJ11,AL11,AN11,,AP11,AR11,AT11,AV11,AX11,AZ11,BB11,BD11) -> 1.0740741 | BG11: =AVERAGE(G11,I11,K11,M11,O11,Q11,S11,U11,W11,Y11,AA11,AC11,AE11,AG11,AI11,AK11,AM11,AO11,AQ11,AS11,AU11,AW11,AY11,BA11,BC11,BE11) -> 0.07967033
A12: 7 | B12: 14 | C12: Van | D12: Celaya | E12: Telcel | F12: =SUM('Paradas Ilpea'!C55:C65) -> 6 | G12: =F12/B12 -> 0.42857143 | H12: =SUM('Paradas Ilpea'!D55:D65) -> 6 | I12: =H12/B12 -> 0.42857143 | J12: =SUM('Paradas Ilpea'!E55:E65) -> 0 | K12: =J12/B12 -> 0 | L12: =SUM('Paradas Ilpea'!F55:F65) -> 7 | M12: =L12/B12 -> 0.5 | N12: =SUM('Paradas Ilpea'!G55:G65) -> 6 | O12: =N12/B12 -> 0.42857143 | P12: =SUM('Paradas Ilpea'!H55:H65) -> 5 | Q12: =P12/B12 -> 0.35714286 | R12: =SUM('Paradas Ilpea'!I55:I65) -> 0 | S12: =R12/B12 -> 0 | T12: =SUM('Paradas Ilpea'!J55:J65) -> 7 | U12: =T12/B12 -> 0.5 | V12: =SUM('Paradas Ilpea'!K55:K65) -> 7 | W12: =V12/B12 -> 0.5 | X12: =SUM('Paradas Ilpea'!L55:L65) -> 5 | Y12: =X12/B12 -> 0.35714286 | Z12: =SUM('Paradas Ilpea'!M55:M65) -> 0 | AA12: =Z12/B12 -> 0 | AB12: =SUM('Paradas Ilpea'!N55:N65) -> 6 | AC12: =AB12/B12 -> 0.42857143 | AD12: =SUM('Paradas Ilpea'!O55:O65) -> 6 | AE12: =AD12/B12 -> 0.42857143 | AF12: =SUM('Paradas Ilpea'!P55:P65) -> 5 | AG12: =AF12/B12 -> 0.35714286 | AH12: =SUM('Paradas Ilpea'!Q55:Q65) -> 0 | AI12: =AH12/B12 -> 0 | AJ12: =SUM('Paradas Ilpea'!R55:R65) -> 7 | AK12: =AJ12/B12 -> 0.5 | AL12: =SUM('Paradas Ilpea'!S55:S65) -> 7 | AM12: =AL12/B12 -> 0.5 | AN12: =SUM('Paradas Ilpea'!T55:T65) -> 5 | AO12: =AN12/B12 -> 0.35714286 | AP12: =SUM('Paradas Ilpea'!U55:U65) -> 0 | AQ12: =AP12/B12 -> 0 | AR12: =SUM('Paradas Ilpea'!V55:V65) -> 7 | AS12: =AR12/B12 -> 0.5 | AT12: =SUM('Paradas Ilpea'!W55:W65) -> 6 | AU12: =AT12/B12 -> 0.42857143 | AV12: =SUM('Paradas Ilpea'!X55:X65) -> 4 | AW12: =AV12/B12 -> 0.28571429 | AX12: =SUM('Paradas Ilpea'!Y55:Y65) -> 0 | AY12: =AX12/B12 -> 0 | AZ12: =SUM('Paradas Ilpea'!Z55:Z65) -> 0 | BA12: =AZ12/B12 -> 0 | BB12: =SUM('Paradas Ilpea'!AA55:AA65) -> 0 | BC12: =BB12/B12 -> 0 | BD12: =SUM('Paradas Ilpea'!AB55:AB65) -> 0 | BE12: =BD12/B12 -> 0 | BF12: =AVERAGE(F12,H12,J12,L12,N12,P12,R12,V12,T12,X12,Z12,AB12,AD12,AF12,AH12,AJ12,AL12,AN12,,AP12,AR12,AT12,AV12,AX12,AZ12,BB12,BD12) -> 3.7777778 | BG12: =AVERAGE(G12,I12,K12,M12,O12,Q12,S12,U12,W12,Y12,AA12,AC12,AE12,AG12,AI12,AK12,AM12,AO12,AQ12,AS12,AU12,AW12,AY12,BA12,BC12,BE12) -> 0.28021978
A13: 8 | B13: 37 | C13: Autobus | D13: San Miguel Octopan | E13: Oxxo | F13: =SUM('Paradas Ilpea'!C66:C72) -> 19 | G13: =F13/B13 -> 0.51351351 | H13: =SUM('Paradas Ilpea'!D66:D72) -> 21 | I13: =H13/B13 -> 0.56756757 | J13: =SUM('Paradas Ilpea'!E66:E72) -> 1 | K13: =J13/B13 -> 0.027027027 | L13: =SUM('Paradas Ilpea'!F66:F72) -> 9 | M13: =L13/B13 -> 0.24324324 | N13: =SUM('Paradas Ilpea'!G66:G72) -> 19 | O13: =N13/B13 -> 0.51351351 | P13: =SUM('Paradas Ilpea'!H66:H72) -> 20 | Q13: =P13/B13 -> 0.54054054 | R13: =SUM('Paradas Ilpea'!I66:I72) -> 1 | S13: =R13/B13 -> 0.027027027 | T13: =SUM('Paradas Ilpea'!J66:J72) -> 10 | U13: =T13/B13 -> 0.27027027 | V13: =SUM('Paradas Ilpea'!K66:K72) -> 19 | W13: =V13/B13 -> 0.51351351 | X13: =SUM('Paradas Ilpea'!L66:L72) -> 21 | Y13: =X13/B13 -> 0.56756757 | Z13: =SUM('Paradas Ilpea'!M66:M72) -> 1 | AA13: =Z13/B13 -> 0.027027027 | AB13: =SUM('Paradas Ilpea'!N66:N72) -> 11 | AC13: =AB13/B13 -> 0.2972973 | AD13: =SUM('Paradas Ilpea'!O66:O72) -> 19 | AE13: =AD13/B13 -> 0.51351351 | AF13: =SUM('Paradas Ilpea'!P66:P72) -> 21 | AG13: =AF13/B13 -> 0.56756757 | AH13: =SUM('Paradas Ilpea'!Q66:Q72) -> 1 | AI13: =AH13/B13 -> 0.027027027 | AJ13: =SUM('Paradas Ilpea'!R66:R72) -> 11 | AK13: =AJ13/B13 -> 0.2972973 | AL13: =SUM('Paradas Ilpea'!S66:S72) -> 19 | AM13: =AL13/B13 -> 0.51351351 | AN13: =SUM('Paradas Ilpea'!T66:T72) -> 21 | AO13: =AN13/B13 -> 0.56756757 | AP13: =SUM('Paradas Ilpea'!U66:U72) -> 1 | AQ13: =AP13/B13 -> 0.027027027 | AR13: =SUM('Paradas Ilpea'!V66:V72) -> 11 | AS13: =AR13/B13 -> 0.2972973 | AT13: =SUM('Paradas Ilpea'!W66:W72) -> 16 | AU13: =AT13/B13 -> 0.43243243 | AV13: =SUM('Paradas Ilpea'!X66:X72) -> 18 | AW13: =AV13/B13 -> 0.48648649 | AX13: =SUM('Paradas Ilpea'!Y66:Y72) -> 0 | AY13: =AX13/B13 -> 0 | AZ13: =SUM('Paradas Ilpea'!Z66:Z72) -> 0 | BA13: =AZ13/B13 -> 0 | BB13: =SUM('Paradas Ilpea'!AA66:AA72) -> 0 | BC13: =BB13/B13 -> 0 | BD13: =SUM('Paradas Ilpea'!AB66:AB72) -> 0 | BE13: =BD13/B13 -> 0 | BF13: =AVERAGE(F13,H13,J13,L13,N13,P13,R13,V13,T13,X13,Z13,AB13,AD13,AF13,AH13,AJ13,AL13,AN13,,AP13,AR13,AT13,AV13,AX13,AZ13,BB13,BD13) -> 10.740741 | BG13: =AVERAGE(G13,I13,K13,M13,O13,Q13,S13,U13,W13,Y13,AA13,AC13,AE13,AG13,AI13,AK13,AM13,AO13,AQ13,AS13,AU13,AW13,AY13,BA13,BC13,BE13) -> 0.3014553
A14: 9 | B14: 37 | C14: Autobus | D14: Apaseo el Alto | E14: Coopel | F14: =SUM('Paradas Ilpea'!C74:C83) -> 24 | G14: =F14/B14 -> 0.64864865 | H14: =SUM('Paradas Ilpea'!D74:D83) -> 9 | I14: =H14/B14 -> 0.24324324 | J14: =SUM('Paradas Ilpea'!E74:E83) -> 0 | K14: =J14/B14 -> 0 | L14: =SUM('Paradas Ilpea'!F74:F83) -> 9 | M14: =L14/B14 -> 0.24324324 | N14: =SUM('Paradas Ilpea'!G74:G83) -> 25 | O14: =N14/B14 -> 0.67567568 | P14: =SUM('Paradas Ilpea'!H74:H83) -> 9 | Q14: =P14/B14 -> 0.24324324 | R14: =SUM('Paradas Ilpea'!I74:I83) -> 0 | S14: =R14/B14 -> 0 | T14: =SUM('Paradas Ilpea'!J74:J83) -> 9 | U14: =T14/B14 -> 0.24324324 | V14: =SUM('Paradas Ilpea'!K74:K83) -> 24 | W14: =V14/B14 -> 0.64864865 | X14: =SUM('Paradas Ilpea'!L74:L83) -> 9 | Y14: =X14/B14 -> 0.24324324 | Z14: =SUM('Paradas Ilpea'!M74:M83) -> 0 | AA14: =Z14/B14 -> 0 | AB14: =SUM('Paradas Ilpea'!N74:N83) -> 9 | AC14: =AB14/B14 -> 0.24324324 | AD14: =SUM('Paradas Ilpea'!O74:O83) -> 25 | AE14: =AD14/B14 -> 0.67567568 | AF14: =SUM('Paradas Ilpea'!P74:P83) -> 9 | AG14: =AF14/B14 -> 0.24324324 | AH14: =SUM('Paradas Ilpea'!Q74:Q83) -> 0 | AI14: =AH14/B14 -> 0 | AJ14: =SUM('Paradas Ilpea'!R74:R83) -> 9 | AK14: =AJ14/B14 -> 0.24324324 | AL14: =SUM('Paradas Ilpea'!S74:S83) -> 25 | AM14: =AL14/B14 -> 0.67567568 | AN14: =SUM('Paradas Ilpea'!T74:T83) -> 9 | AO14: =AN14/B14 -> 0.24324324 | AP14: =SUM('Paradas Ilpea'!U74:U83) -> 0 | AQ14: =AP14/B14 -> 0 | AR14: =SUM('Paradas Ilpea'!V74:V83) -> 9 | AS14: =AR14/B14 -> 0.24324324 | AT14: =SUM('Paradas Ilpea'!W74:W83) -> 12 | AU14: =AT14/B14 -> 0.32432432 | AV14: =SUM('Paradas Ilpea'!X74:X83) -> 7 | AW14: =AV14/B14 -> 0.18918919 | AX14: =SUM('Paradas Ilpea'!Y74:Y83) -> 0 | AY14: =AX14/B14 -> 0 | AZ14: =SUM('Paradas Ilpea'!Z74:Z83) -> 0 | BA14: =AZ14/B14 -> 0 | BB14: =SUM('Paradas Ilpea'!AA74:AA83) -> 0 | BC14: =BB14/B14 -> 0 | BD14: =SUM('Paradas Ilpea'!AB74:AB83) -> 0 | BE14: =BD14/B14 -> 0 | BF14: =AVERAGE(F14,H14,J14,L14,N14,P14,R14,V14,T14,X14,Z14,AB14,AD14,AF14,AH14,AJ14,AL14,AN14,,AP14,AR14,AT14,AV14,AX14,AZ14,BB14,BD14) -> 8.5925926 | BG14: =AVERAGE(G14,I14,K14,M14,O14,Q14,S14,U14,W14,Y14,AA14,AC14,AE14,AG14,AI14,AK14,AM14,AO14,AQ14,AS14,AU14,AW14,AY14,BA14,BC14,BE14) -> 0.24116424
A15: 10 | B15: 13 | C15: Van | D15: Tierra Blanca | E15: Tierra blanca | F15: =SUM('Paradas Ilpea'!C84:C90) -> 10 | G15: =F15/B15 -> 0.76923077 | H15: =SUM('Paradas Ilpea'!D84:D90) -> 7 | I15: =H15/B15 -> 0.53846154 | J15: =SUM('Paradas Ilpea'!E84:E90) -> 0 | K15: =J15/B15 -> 0 | L15: =SUM('Paradas Ilpea'!F84:F90) -> 5 | M15: =L15/B15 -> 0.38461538 | N15: =SUM('Paradas Ilpea'!G84:G90) -> 14 | O15: =N15/B15 -> 1.0769231 | P15: =SUM('Paradas Ilpea'!H84:H90) -> 7 | Q15: =P15/B15 -> 0.53846154 | R15: =SUM('Paradas Ilpea'!I84:I90) -> 0 | S15: =R15/B15 -> 0 | T15: =SUM('Paradas Ilpea'!J84:J90) -> 5 | U15: =T15/B15 -> 0.38461538 | V15: =SUM('Paradas Ilpea'!K84:K90) -> 10 | W15: =V15/B15 -> 0.76923077 | X15: =SUM('Paradas Ilpea'!L84:L90) -> 7 | Y15: =X15/B15 -> 0.53846154 | Z15: =SUM('Paradas Ilpea'!M84:M90) -> 0 | AA15: =Z15/B15 -> 0 | AB15: =SUM('Paradas Ilpea'!N84:N90) -> 4 | AC15: =AB15/B15 -> 0.30769231 | AD15: =SUM('Paradas Ilpea'!O84:O90) -> 13 | AE15: =AD15/B15 -> 1 | AF15: =SUM('Paradas Ilpea'!P84:P90) -> 7 | AG15: =AF15/B15 -> 0.53846154 | AH15: =SUM('Paradas Ilpea'!Q84:Q90) -> 0 | AI15: =AH15/B15 -> 0 | AJ15: =SUM('Paradas Ilpea'!R84:R90) -> 5 | AK15: =AJ15/B15 -> 0.38461538 | AL15: =SUM('Paradas Ilpea'!S84:S90) -> 13 | AM15: =AL15/B15 -> 1 | AN15: =SUM('Paradas Ilpea'!T84:T95) -> 6 | AO15: =AN15/B15 -> 0.46153846 | AP15: =SUM('Paradas Ilpea'!U84:U95) -> 0 | AQ15: =AP15/B15 -> 0 | AR15: =SUM('Paradas Ilpea'!V84:V90) -> 5 | AS15: =AR15/B15 -> 0.38461538 | AT15: =SUM('Paradas Ilpea'!W84:W90) -> 12 | AU15: =AT15/B15 -> 0.92307692 | AV15: =SUM('Paradas Ilpea'!X84:X90) -> 8 | AW15: =AV15/B15 -> 0.61538462 | AX15: =SUM('Paradas Ilpea'!Y84:Y90) -> 0 | AY15: =AX15/B15 -> 0 | AZ15: =SUM('Paradas Ilpea'!Z84:Z90) -> 0 | BA15: =AZ15/B15 -> 0 | BB15: =SUM('Paradas Ilpea'!AA84:AA90) -> 0 | BC15: =BB15/B15 -> 0 | BD15: =SUM('Paradas Ilpea'!AB84:AB90) -> 0 | BE15: =BD15/B15 -> 0 | BF15: =AVERAGE(F15,H15,J15,L15,N15,P15,R15,V15,T15,X15,Z15,AB15,AD15,AF15,AH15,AJ15,AL15,AN15,,AP15,AR15,AT15,AV15,AX15,AZ15,BB15,BD15) -> 5.1111111 | BG15: =AVERAGE(G15,I15,K15,M15,O15,Q15,S15,U15,W15,Y15,AA15,AC15,AE15,AG15,AI15,AK15,AM15,AO15,AQ15,AS15,AU15,AW15,AY15,BA15,BC15,BE15) -> 0.40828402
A16: 14 | B16: 13 | C16: Van | D16: Picaho | E16: Frente al Templo | F16: =SUM('Paradas Ilpea'!C91:C101) -> 3 | G16: =F16/B16 -> 0.23076923 | H16: =SUM('Paradas Ilpea'!D91:D101) -> 3 | I16: =H16/B16 -> 0.23076923 | J16: =SUM('Paradas Ilpea'!E91:E101) -> 0 | K16: =J16/B16 -> 0 | L16: =SUM('Paradas Ilpea'!F91:F101) -> 4 | M16: =L16/B16 -> 0.30769231 | N16: =SUM('Paradas Ilpea'!G91:G101) -> 1 | O16: =N16/B16 -> 0.076923077 | P16: =SUM('Paradas Ilpea'!H91:H101) -> 2 | Q16: =P16/B16 -> 0.15384615 | R16: =SUM('Paradas Ilpea'!I91:I101) -> 0 | S16: =R16/B16 -> 0 | T16: =SUM('Paradas Ilpea'!J91:J101) -> 0 | U16: =T16/B16 -> 0 | V16: =SUM('Paradas Ilpea'!K91:K101) -> 2 | W16: =V16/B16 -> 0.15384615 | X16: =SUM('Paradas Ilpea'!L91:L101) -> 2 | Y16: =X16/B16 -> 0.15384615 | Z16: =SUM('Paradas Ilpea'!M91:M101) -> 0 | AA16: =Z16/B16 -> 0 | AB16: =SUM('Paradas Ilpea'!N91:N101) -> 0 | AC16: =AB16/B16 -> 0 | AD16: =SUM('Paradas Ilpea'!O91:O101) -> 3 | AE16: =AD16/B16 -> 0.23076923 | AF16: =SUM('Paradas Ilpea'!P91:P101) -> 2 | AG16: =AF16/B16 -> 0.15384615 | AH16: =SUM('Paradas Ilpea'!Q91:Q101) -> 0 | AI16: =AH16/B16 -> 0 | AJ16: =SUM('Paradas Ilpea'!R91:R101) -> 0 | AK16: =AJ16/B16 -> 0 | AL16: =SUM('Paradas Ilpea'!S91:S101) -> 2 | AM16: =AL16/B16 -> 0.15384615 | AN16: =SUM('Paradas Ilpea'!T96:T101) -> 1 | AO16: =AN16/B16 -> 0.076923077 | AP16: =SUM('Paradas Ilpea'!U96:U101) -> 0 | AQ16: =AP16/B16 -> 0 | AR16: =SUM('Paradas Ilpea'!V91:V101) -> 0 | AS16: =AR16/B16 -> 0 | AT16: =SUM('Paradas Ilpea'!W91:W101) -> 1 | AU16: =AT16/B16 -> 0.076923077 | AV16: =SUM('Paradas Ilpea'!X91:X101) -> 2 | AW16: =AV16/B16 -> 0.15384615 | AX16: =SUM('Paradas Ilpea'!Y91:Y101) -> 0 | AY16: =AX16/B16 -> 0 | AZ16: =SUM('Paradas Ilpea'!Z91:Z101) -> 0 | BA16: =AZ16/B16 -> 0 | BB16: =SUM('Paradas Ilpea'!AA91:AA101) -> 0 | BC16: =BB16/B16 -> 0 | BD16: =SUM('Paradas Ilpea'!AB91:AB101) -> 0 | BE16: =BD16/B16 -> 0 | BF16: =AVERAGE(F16,H16,J16,L16,N16,P16,R16,V16,T16,X16,Z16,AB16,AD16,AF16,AH16,AJ16,AL16,AN16,,AP16,AR16,AT16,AV16,AX16,AZ16,BB16,BD16) -> 1.037037 | BG16: =AVERAGE(G16,I16,K16,M16,O16,Q16,S16,U16,W16,Y16,AA16,AC16,AE16,AG16,AI16,AK16,AM16,AO16,AQ16,AS16,AU16,AW16,AY16,BA16,BC16,BE16) -> 0.082840237

Sheet Rutas Adm
A3: Ruta | B3: Paradas | C3: 46090 | D3: =C3+1 -> 46091 | E3: =D3+1 -> 46092 | F3: =E3+1 -> 46093 | G3: =F3+1 -> 46094 | H3: =G3+1 -> 46095
C4: Usuarios | D4: Usuarios | E4: Usuarios | F4: Usuarios | G4: Usuarios | H4: Usuarios
A5: 5 | B5: 1 | C5: 1 | D5: 1 | E5: 1 | F5: 1 | G5: 1
A6: 5 | B6: 2 | C6: 1 | D6: 1 | E6: 1 | F6: 1 | G6: 1
A7: 5 | B7: 3 | C7: 1 | D7: 1 | E7: 1 | F7: 1 | G7: 1
A8: 5 | B8: 4 | C8: 2 | D8: 2 | E8: 2 | F8: 2 | G8: 2
A9: 5 | B9: 5 | C9: 1 | D9: 1 | E9: 1 | F9: 1 | G9: 1 | L9: 14
A10: 5 | B10: 6 | C10: 1 | D10: 1 | E10: 1 | F10: 1 | G10: 1
C11: =SUM(C5:C10) -> 7 | D11: 0 | E11: =SUM(E5:E10) -> 7 | F11: =SUM(F5:F10) -> 7 | G11: =SUM(G5:G10) -> 7 | H11: =SUM(H5:H10) -> 0
A12: Porcentaje de Ocupación | C12: =C11/L9 -> 0.5 | D12: =D11/L9 -> 0 | E12: =E11/L9 -> 0.5 | F12: =F11/L9 -> 0.5 | G12: =G11/L9 -> 0.5
A14: 11 | B14: 1 | C14: 4 | D14: 4 | E14: 4 | F14: 4 | G14: 4
A15: 11 | B15: 2 | C15: 0 | D15: 0 | E15: 0 | F15: 0 | G15: 0
A16: 11 | B16: 3 | C16: 1 | D16: 1 | E16: 1 | F16: 1 | G16: 1
A17: 11 | B17: 4 | C17: 0 | D17: 0 | E17: 0 | F17: 0 | G17: 0
A18: 11 | B18: 5 | C18: 1 | D18: 1 | E18: 1 | F18: 1 | G18: 1 | L18: 14
A19: 11 | B19: 6 | C19: 3 | D19: 3 | E19: 3 | F19: 3 | G19: 3
A20: 11 | B20: 7 | C20: 1 | D20: 1 | E20: 1 | F20: 1 | G20: 1
C21: =SUM(C14:C20) -> 10 | D21: 0 | E21: =SUM(E14:E20) -> 10 | F21: =SUM(F14:F20) -> 10 | G21: =SUM(G14:G20) -> 10 | H21: =SUM(H14:H20) -> 0
A22: Porcentaje de Ocupación | C22: =C21/L18 -> 0.71428571 | D22: =D21/L18 -> 0 | E22: =E21/L18 -> 0.71428571 | F22: =F21/L18 -> 0.71428571 | G22: =G21/L18 -> 0.71428571
A23: 12 | B23: 1 | C23: 3 | D23: 3 | E23: 3 | F23: 3 | G23: 3
A24: 12 | B24: 2 | C24: 1 | D24: 1 | E24: 1 | F24: 1 | G24: 1
A25: 12 | B25: 3 | C25: 3 | D25: 3 | E25: 3 | F25: 3 | G25: 3
A26: 12 | B26: 4 | C26: 1 | D26: 1 | E26: 1 | F26: 1 | G26: 1
A27: 12 | B27: 5 | C27: 1 | D27: 1 | E27: 1 | F27: 1 | G27: 1 | L27: 14
A28: 12 | B28: 6 | C28: 1 | D28: 1 | E28: 1 | F28: 1 | G28: 1
A29: 12 | B29: 7 | C29: 1 | D29: 1 | E29: 1 | F29: 1 | G29: 1
A30: 12 | B30: 8 | C30: 0 | D30: 0 | E30: 0 | F30: 0 | G30: 0
C31: =SUM(C23:C30) -> 11 | D31: =SUM(D23:D30) -> 11 | E31: =SUM(E23:E29) -> 11 | F31: =SUM(F23:F30) -> 11 | G31: =SUM(G23:G29) -> 11 | H31: =SUM(H23:H28) -> 0
A32: Porcentaje de Ocupación | C32: =C31/L27 -> 0.78571429 | D32: =D31/L27 -> 0.78571429 | E32: =E31/L27 -> 0.78571429 | F32: =F31/L27 -> 0.78571429 | G32: =G31/L27 -> 0.78571429
A33: 13 | B33: 1 | C33: 0 | D33: 0 | E33: 0 | F33: 0 | G33: 0
A34: 13 | B34: 2 | C34: 2 | D34: 2 | E34: 2 | F34: 2 | G34: 2
A35: 13 | B35: 3 | C35: 1 | D35: 1 | E35: 1 | F35: 1 | G35: 1
A36: 13 | B36: 4 | C36: 1 | D36: 1 | E36: 1 | F36: 1 | G36: 1
A37: 13 | B37: 5 | C37: 1 | D37: 1 | E37: 1 | F37: 1 | G37: 1 | L37: 14
A38: 13 | B38: 6 | C38: 0 | D38: 0 | E38: 0 | F38: 0 | G38: 0
A39: 13 | B39: 7 | C39: 1 | D39: 1 | E39: 1 | F39: 1 | G39: 1
C40: =SUM(C33:C39) -> 6 | D40: =SUM(D33:D39) -> 6 | E40: =SUM(E33:E39) -> 6 | F40: =SUM(F33:F39) -> 6 | G40: =SUM(G33:G39) -> 6 | H40: =SUM(H33:H39) -> 0
A41: Porcentaje de Ocupación | C41: =C40/L37 -> 0.42857143 | D41: =D40/L37 -> 0.42857143 | E41: =E40/L37 -> 0.42857143 | F41: =F40/L37 -> 0.42857143 | G41: =G40/L37 -> 0.42857143
